Workbook

Sheet at_a_glance
A1: At a glance
A2: Today and the next six days
A5: =IF($A$30="","","TODAY "&TEXT($A$30,"dddd")) | B5: =IF($A$32="","",$A$32&" month "&$A$37&IF(OR($A$37=1,$A$37=5,$A$37=9)," * LONG FAST","")) | C5: =IF($A$39="yes","六齋日 FAST DAY","")
A6: =IF($A$30="","",TEXT($A$30,"d mmm yyyy")) | B6: =IF($A$33="","",$A$33&" day "&$A$34&IF($A$38="LEAP"," (LEAP MONTH)","")) | C6: =IF($A$40="","",$A$40&" moon")
A8: =IF($B$30="","",TEXT($B$30,"dddd")) | B8: =IF($B$32="","",$B$32&" month "&$B$37&IF(OR($B$37=1,$B$37=5,$B$37=9)," * LONG FAST","")) | C8: =IF($B$39="yes","六齋日 FAST DAY","")
A9: =IF($B$30="","",TEXT($B$30,"d mmm yyyy")) | B9: =IF($B$33="","",$B$33&" day "&$B$34&IF($B$38="LEAP"," (LEAP MONTH)","")) | C9: =IF($B$40="","",$B$40&" moon")
A11: =IF($C$30="","",TEXT($C$30,"dddd")) | B11: =IF($C$32="","",$C$32&" month "&$C$37&IF(OR($C$37=1,$C$37=5,$C$37=9)," * LONG FAST","")) | C11: =IF($C$39="yes","六齋日 FAST DAY","")
A12: =IF($C$30="","",TEXT($C$30,"d mmm yyyy")) | B12: =IF($C$33="","",$C$33&" day "&$C$34&IF($C$38="LEAP"," (LEAP MONTH)","")) | C12: =IF($C$40="","",$C$40&" moon")
A14: =IF($D$30="","",TEXT($D$30,"dddd")) | B14: =IF($D$32="","",$D$32&" month "&$D$37&IF(OR($D$37=1,$D$37=5,$D$37=9)," * LONG FAST","")) | C14: =IF($D$39="yes","六齋日 FAST DAY","")
A15: =IF($D$30="","",TEXT($D$30,"d mmm yyyy")) | B15: =IF($D$33="","",$D$33&" day "&$D$34&IF($D$38="LEAP"," (LEAP MONTH)","")) | C15: =IF($D$40="","",$D$40&" moon")
A17: =IF($E$30="","",TEXT($E$30,"dddd")) | B17: =IF($E$32="","",$E$32&" month "&$E$37&IF(OR($E$37=1,$E$37=5,$E$37=9)," * LONG FAST","")) | C17: =IF($E$39="yes","六齋日 FAST DAY","")
A18: =IF($E$30="","",TEXT($E$30,"d mmm yyyy")) | B18: =IF($E$33="","",$E$33&" day "&$E$34&IF($E$38="LEAP"," (LEAP MONTH)","")) | C18: =IF($E$40="","",$E$40&" moon")
A20: =IF($F$30="","",TEXT($F$30,"dddd")) | B20: =IF($F$32="","",$F$32&" month "&$F$37&IF(OR($F$37=1,$F$37=5,$F$37=9)," * LONG FAST","")) | C20: =IF($F$39="yes","六齋日 FAST DAY","")
A21: =IF($F$30="","",TEXT($F$30,"d mmm yyyy")) | B21: =IF($F$33="","",$F$33&" day "&$F$34&IF($F$38="LEAP"," (LEAP MONTH)","")) | C21: =IF($F$40="","",$F$40&" moon")
A23: =IF($G$30="","",TEXT($G$30,"dddd")) | B23: =IF($G$32="","",$G$32&" month "&$G$37&IF(OR($G$37=1,$G$37=5,$G$37=9)," * LONG FAST","")) | C23: =IF($G$39="yes","六齋日 FAST DAY","")
A24: =IF($G$30="","",TEXT($G$30,"d mmm yyyy")) | B24: =IF($G$33="","",$G$33&" day "&$G$34&IF($G$38="LEAP"," (LEAP MONTH)","")) | C24: =IF($G$40="","",$G$40&" moon")
A27: Settings
A28: Showing from | B28: =TODAY()
A29: Overwrite that date to preview another week. Put =TODAY() back to return to normal.
A30: =$B$28+0 | B30: =$B$28+1 | C30: =$B$28+2 | D30: =$B$28+3 | E30: =$B$28+4 | F30: =$B$28+5 | G30: =$B$28+6 | I30: date
A31: =IFERROR(MATCH(A$30,lunar_ref!$A:$A,0),"") | B31: =IFERROR(MATCH(B$30,lunar_ref!$A:$A,0),"") | C31: =IFERROR(MATCH(C$30,lunar_ref!$A:$A,0),"") | D31: =IFERROR(MATCH(D$30,lunar_ref!$A:$A,0),"") | E31: =IFERROR(MATCH(E$30,lunar_ref!$A:$A,0),"") | F31: =IFERROR(MATCH(F$30,lunar_ref!$A:$A,0),"") | G31: =IFERROR(MATCH(G$30,lunar_ref!$A:$A,0),"") | I31: lunar_ref row
A32: =IFERROR(INDEX(lunar_ref!$B:$B,A$31),"") | B32: =IFERROR(INDEX(lunar_ref!$B:$B,B$31),"") | C32: =IFERROR(INDEX(lunar_ref!$B:$B,C$31),"") | D32: =IFERROR(INDEX(lunar_ref!$B:$B,D$31),"") | E32: =IFERROR(INDEX(lunar_ref!$B:$B,E$31),"") | F32: =IFERROR(INDEX(lunar_ref!$B:$B,F$31),"") | G32: =IFERROR(INDEX(lunar_ref!$B:$B,G$31),"") | I32: lunar month
A33: =IFERROR(INDEX(lunar_ref!$C:$C,A$31),"") | B33: =IFERROR(INDEX(lunar_ref!$C:$C,B$31),"") | C33: =IFERROR(INDEX(lunar_ref!$C:$C,C$31),"") | D33: =IFERROR(INDEX(lunar_ref!$C:$C,D$31),"") | E33: =IFERROR(INDEX(lunar_ref!$C:$C,E$31),"") | F33: =IFERROR(INDEX(lunar_ref!$C:$C,F$31),"") | G33: =IFERROR(INDEX(lunar_ref!$C:$C,G$31),"") | I33: lunar day
A34: =IFERROR(INDEX(lookup!$B:$B,MATCH(A$33,lookup!$A:$A,0)),"") | B34: =IFERROR(INDEX(lookup!$B:$B,MATCH(B$33,lookup!$A:$A,0)),"") | C34: =IFERROR(INDEX(lookup!$B:$B,MATCH(C$33,lookup!$A:$A,0)),"") | D34: =IFERROR(INDEX(lookup!$B:$B,MATCH(D$33,lookup!$A:$A,0)),"") | E34: =IFERROR(INDEX(lookup!$B:$B,MATCH(E$33,lookup!$A:$A,0)),"") | F34: =IFERROR(INDEX(lookup!$B:$B,MATCH(F$33,lookup!$A:$A,0)),"") | G34: =IFERROR(INDEX(lookup!$B:$B,MATCH(G$33,lookup!$A:$A,0)),"") | I34: day number
A35: =IFERROR(INDEX(lookup!$B:$B,MATCH(INDEX(lunar_ref!$C:$C,A$31+1),lookup!$A:$A,0)),"") | B35: =IFERROR(INDEX(lookup!$B:$B,MATCH(INDEX(lunar_ref!$C:$C,B$31+1),lookup!$A:$A,0)),"") | C35: =IFERROR(INDEX(lookup!$B:$B,MATCH(INDEX(lunar_ref!$C:$C,C$31+1),lookup!$A:$A,0)),"") | D35: =IFERROR(INDEX(lookup!$B:$B,MATCH(INDEX(lunar_ref!$C:$C,D$31+1),lookup!$A:$A,0)),"") | E35: =IFERROR(INDEX(lookup!$B:$B,MATCH(INDEX(lunar_ref!$C:$C,E$31+1),lookup!$A:$A,0)),"") | F35: =IFERROR(INDEX(lookup!$B:$B,MATCH(INDEX(lunar_ref!$C:$C,F$31+1),lookup!$A:$A,0)),"") | G35: =IFERROR(INDEX(lookup!$B:$B,MATCH(INDEX(lunar_ref!$C:$C,G$31+1),lookup!$A:$A,0)),"") | I35: day+1 number
A36: =IFERROR(INDEX(lookup!$B:$B,MATCH(INDEX(lunar_ref!$C:$C,A$31+2),lookup!$A:$A,0)),"") | B36: =IFERROR(INDEX(lookup!$B:$B,MATCH(INDEX(lunar_ref!$C:$C,B$31+2),lookup!$A:$A,0)),"") | C36: =IFERROR(INDEX(lookup!$B:$B,MATCH(INDEX(lunar_ref!$C:$C,C$31+2),lookup!$A:$A,0)),"") | D36: =IFERROR(INDEX(lookup!$B:$B,MATCH(INDEX(lunar_ref!$C:$C,D$31+2),lookup!$A:$A,0)),"") | E36: =IFERROR(INDEX(lookup!$B:$B,MATCH(INDEX(lunar_ref!$C:$C,E$31+2),lookup!$A:$A,0)),"") | F36: =IFERROR(INDEX(lookup!$B:$B,MATCH(INDEX(lunar_ref!$C:$C,F$31+2),lookup!$A:$A,0)),"") | G36: =IFERROR(INDEX(lookup!$B:$B,MATCH(INDEX(lunar_ref!$C:$C,G$31+2),lookup!$A:$A,0)),"") | I36: day+2 number
A37: =IFERROR(INDEX(lookup!$E:$E,MATCH(A$32,lookup!$D:$D,0)),"") | B37: =IFERROR(INDEX(lookup!$E:$E,MATCH(B$32,lookup!$D:$D,0)),"") | C37: =IFERROR(INDEX(lookup!$E:$E,MATCH(C$32,lookup!$D:$D,0)),"") | D37: =IFERROR(INDEX(lookup!$E:$E,MATCH(D$32,lookup!$D:$D,0)),"") | E37: =IFERROR(INDEX(lookup!$E:$E,MATCH(E$32,lookup!$D:$D,0)),"") | F37: =IFERROR(INDEX(lookup!$E:$E,MATCH(F$32,lookup!$D:$D,0)),"") | G37: =IFERROR(INDEX(lookup!$E:$E,MATCH(G$32,lookup!$D:$D,0)),"") | I37: month number
A38: =IFERROR(INDEX(lookup!$G:$G,MATCH(A$32,lookup!$D:$D,0)),"") | B38: =IFERROR(INDEX(lookup!$G:$G,MATCH(B$32,lookup!$D:$D,0)),"") | C38: =IFERROR(INDEX(lookup!$G:$G,MATCH(C$32,lookup!$D:$D,0)),"") | D38: =IFERROR(INDEX(lookup!$G:$G,MATCH(D$32,lookup!$D:$D,0)),"") | E38: =IFERROR(INDEX(lookup!$G:$G,MATCH(E$32,lookup!$D:$D,0)),"") | F38: =IFERROR(INDEX(lookup!$G:$G,MATCH(F$32,lookup!$D:$D,0)),"") | G38: =IFERROR(INDEX(lookup!$G:$G,MATCH(G$32,lookup!$D:$D,0)),"") | I38: leap?
A39: =IF(A$34="","",IF(OR(A$34=8,A$34=14,A$34=15,A$34=23,A$35=1,A$36=1),"yes","")) | B39: =IF(B$34="","",IF(OR(B$34=8,B$34=14,B$34=15,B$34=23,B$35=1,B$36=1),"yes","")) | C39: =IF(C$34="","",IF(OR(C$34=8,C$34=14,C$34=15,C$34=23,C$35=1,C$36=1),"yes","")) | D39: =IF(D$34="","",IF(OR(D$34=8,D$34=14,D$34=15,D$34=23,D$35=1,D$36=1),"yes","")) | E39: =IF(E$34="","",IF(OR(E$34=8,E$34=14,E$34=15,E$34=23,E$35=1,E$36=1),"yes","")) | F39: =IF(F$34="","",IF(OR(F$34=8,F$34=14,F$34=15,F$34=23,F$35=1,F$36=1),"yes","")) | G39: =IF(G$34="","",IF(OR(G$34=8,G$34=14,G$34=15,G$34=23,G$35=1,G$36=1),"yes","")) | I39: fast day
A40: =IF(A$34=1,"New",IF(A$34=15,"Full","")) | B40: =IF(B$34=1,"New",IF(B$34=15,"Full","")) | C40: =IF(C$34=1,"New",IF(C$34=15,"Full","")) | D40: =IF(D$34=1,"New",IF(D$34=15,"Full","")) | E40: =IF(E$34=1,"New",IF(E$34=15,"Full","")) | F40: =IF(F$34=1,"New",IF(F$34=15,"Full","")) | G40: =IF(G$34=1,"New",IF(G$34=15,"Full","")) | I40: moon

Sheet drba
A1: date | B1: weekday | C1: lunar_month | D1: lunar_day | E1: lunar_day_eng | F1: moon_phase | G1: dharma_event | H1: 六齋日 | I1: lunar_month_eng | J1: 三長齋月 | K1: leap_month
A2: 46246 | B2: =TEXT(A2,"ddd") | C2: 六月 | D2: 三十 | E2: {=_xlfn.XLOOKUP($D2,lookup!$A:$A,lookup!$B:$B)} | H2: =IF($E2="","",IF(OR($E2=8,$E2=14,$E2=15,$E2=23,$E3=1,$E4=1),"Fast day","")) | I2: =IFERROR(INDEX(lookup!$E:$E,MATCH($C2,lookup!$D:$D,0)),"") | J2: =IF($I2="","",IF(OR($I2=1,$I2=5,$I2=9),IF($K2="","Long fast month","Long fast month (LEAP)"),"")) | K2: =IFERROR(IF(INDEX(lookup!$G:$G,MATCH($C2,lookup!$D:$D,0))="LEAP","LEAP MONTH - counts as month "&$I2&", flagged for review",""),"")
A3: =A2+1 | B3: =TEXT(A3,"ddd") | C3: 七月 | D3: 初一 | E3: {=_xlfn.XLOOKUP($D3,lookup!$A:$A,lookup!$B:$B)} | F3: New | H3: =IF($E3="","",IF(OR($E3=8,$E3=14,$E3=15,$E3=23,$E4=1,$E5=1),"Fast day","")) | I3: =IFERROR(INDEX(lookup!$E:$E,MATCH($C3,lookup!$D:$D,0)),"") | J3: =IF($I3="","",IF(OR($I3=1,$I3=5,$I3=9),IF($K3="","Long fast month","Long fast month (LEAP)"),"")) | K3: =IFERROR(IF(INDEX(lookup!$G:$G,MATCH($C3,lookup!$D:$D,0))="LEAP","LEAP MONTH - counts as month "&$I3&", flagged for review",""),"")
A4: =A3+1 | B4: =TEXT(A4,"ddd") | C4: =IF($E4=1,"?",C3) | D4: 初二 | E4: {=_xlfn.XLOOKUP($D4,lookup!$A:$A,lookup!$B:$B)} | H4: =IF($E4="","",IF(OR($E4=8,$E4=14,$E4=15,$E4=23,$E5=1,$E6=1),"Fast day","")) | I4: =IFERROR(INDEX(lookup!$E:$E,MATCH($C4,lookup!$D:$D,0)),"") | J4: =IF($I4="","",IF(OR($I4=1,$I4=5,$I4=9),IF($K4="","Long fast month","Long fast month (LEAP)"),"")) | K4: =IFERROR(IF(INDEX(lookup!$G:$G,MATCH($C4,lookup!$D:$D,0))="LEAP","LEAP MONTH - counts as month "&$I4&", flagged for review",""),"")
A5: =A4+1 | B5: =TEXT(A5,"ddd") | C5: =IF($E5=1,"?",C4) | D5: 初三 | E5: {=_xlfn.XLOOKUP($D5,lookup!$A:$A,lookup!$B:$B)} | H5: =IF($E5="","",IF(OR($E5=8,$E5=14,$E5=15,$E5=23,$E6=1,$E7=1),"Fast day","")) | I5: =IFERROR(INDEX(lookup!$E:$E,MATCH($C5,lookup!$D:$D,0)),"") | J5: =IF($I5="","",IF(OR($I5=1,$I5=5,$I5=9),IF($K5="","Long fast month","Long fast month (LEAP)"),"")) | K5: =IFERROR(IF(INDEX(lookup!$G:$G,MATCH($C5,lookup!$D:$D,0))="LEAP","LEAP MONTH - counts as month "&$I5&", flagged for review",""),"")
A6: =A5+1 | B6: =TEXT(A6,"ddd") | C6: =IF($E6=1,"?",C5) | D6: 初四 | E6: {=_xlfn.XLOOKUP($D6,lookup!$A:$A,lookup!$B:$B)} | H6: =IF($E6="","",IF(OR($E6=8,$E6=14,$E6=15,$E6=23,$E7=1,$E8=1),"Fast day","")) | I6: =IFERROR(INDEX(lookup!$E:$E,MATCH($C6,lookup!$D:$D,0)),"") | J6: =IF($I6="","",IF(OR($I6=1,$I6=5,$I6=9),IF($K6="","Long fast month","Long fast month (LEAP)"),"")) | K6: =IFERROR(IF(INDEX(lookup!$G:$G,MATCH($C6,lookup!$D:$D,0))="LEAP","LEAP MONTH - counts as month "&$I6&", flagged for review",""),"")
A7: =A6+1 | B7: =TEXT(A7,"ddd") | C7: =IF($E7=1,"?",C6) | D7: 初五 | E7: {=_xlfn.XLOOKUP($D7,lookup!$A:$A,lookup!$B:$B)} | H7: =IF($E7="","",IF(OR($E7=8,$E7=14,$E7=15,$E7=23,$E8=1,$E9=1),"Fast day","")) | I7: =IFERROR(INDEX(lookup!$E:$E,MATCH($C7,lookup!$D:$D,0)),"") | J7: =IF($I7="","",IF(OR($I7=1,$I7=5,$I7=9),IF($K7="","Long fast month","Long fast month (LEAP)"),"")) | K7: =IFERROR(IF(INDEX(lookup!$G:$G,MATCH($C7,lookup!$D:$D,0))="LEAP","LEAP MONTH - counts as month "&$I7&", flagged for review",""),"")
A8: =A7+1 | B8: =TEXT(A8,"ddd") | C8: =IF($E8=1,"?",C7) | D8: 初六 | E8: {=_xlfn.XLOOKUP($D8,lookup!$A:$A,lookup!$B:$B)} | H8: =IF($E8="","",IF(OR($E8=8,$E8=14,$E8=15,$E8=23,$E9=1,$E10=1),"Fast day","")) | I8: =IFERROR(INDEX(lookup!$E:$E,MATCH($C8,lookup!$D:$D,0)),"") | J8: =IF($I8="","",IF(OR($I8=1,$I8=5,$I8=9),IF($K8="","Long fast month","Long fast month (LEAP)"),"")) | K8: =IFERROR(IF(INDEX(lookup!$G:$G,MATCH($C8,lookup!$D:$D,0))="LEAP","LEAP MONTH - counts as month "&$I8&", flagged for review",""),"")
A9: =A8+1 | B9: =TEXT(A9,"ddd") | C9: =IF($E9=1,"?",C8) | D9: 初七 | E9: {=_xlfn.XLOOKUP($D9,lookup!$A:$A,lookup!$B:$B)} | H9: =IF($E9="","",IF(OR($E9=8,$E9=14,$E9=15,$E9=23,$E10=1,$E11=1),"Fast day","")) | I9: =IFERROR(INDEX(lookup!$E:$E,MATCH($C9,lookup!$D:$D,0)),"") | J9: =IF($I9="","",IF(OR($I9=1,$I9=5,$I9=9),IF($K9="","Long fast month","Long fast month (LEAP)"),"")) | K9: =IFERROR(IF(INDEX(lookup!$G:$G,MATCH($C9,lookup!$D:$D,0))="LEAP","LEAP MONTH - counts as month "&$I9&", flagged for review",""),"")
A10: =A9+1 | B10: =TEXT(A10,"ddd") | C10: =IF($E10=1,"?",C9) | D10: 初八 | E10: {=_xlfn.XLOOKUP($D10,lookup!$A:$A,lookup!$B:$B)} | H10: =IF($E10="","",IF(OR($E10=8,$E10=14,$E10=15,$E10=23,$E11=1,$E12=1),"Fast day","")) | I10: =IFERROR(INDEX(lookup!$E:$E,MATCH($C10,lookup!$D:$D,0)),"") | J10: =IF($I10="","",IF(OR($I10=1,$I10=5,$I10=9),IF($K10="","Long fast month","Long fast month (LEAP)"),"")) | K10: =IFERROR(IF(INDEX(lookup!$G:$G,MATCH($C10,lookup!$D:$D,0))="LEAP","LEAP MONTH - counts as month "&$I10&", flagged for review",""),"")
A11: =A10+1 | B11: =TEXT(A11,"ddd") | C11: =IF($E11=1,"?",C10) | D11: 初九 | E11: {=_xlfn.XLOOKUP($D11,lookup!$A:$A,lookup!$B:$B)} | H11: =IF($E11="","",IF(OR($E11=8,$E11=14,$E11=15,$E11=23,$E12=1,$E13=1),"Fast day","")) | I11: =IFERROR(INDEX(lookup!$E:$E,MATCH($C11,lookup!$D:$D,0)),"") | J11: =IF($I11="","",IF(OR($I11=1,$I11=5,$I11=9),IF($K11="","Long fast month","Long fast month (LEAP)"),"")) | K11: =IFERROR(IF(INDEX(lookup!$G:$G,MATCH($C11,lookup!$D:$D,0))="LEAP","LEAP MONTH - counts as month "&$I11&", flagged for review",""),"")
A12: =A11+1 | B12: =TEXT(A12,"ddd") | C12: =IF($E12=1,"?",C11) | D12: 初十 | E12: {=_xlfn.XLOOKUP($D12,lookup!$A:$A,lookup!$B:$B)} | G12: Monthly Memorial of Venerable Master Hua’s Entering Nirvana | H12: =IF($E12="","",IF(OR($E12=8,$E12=14,$E12=15,$E12=23,$E13=1,$E14=1),"Fast day","")) | I12: =IFERROR(INDEX(lookup!$E:$E,MATCH($C12,lookup!$D:$D,0)),"") | J12: =IF($I12="","",IF(OR($I12=1,$I12=5,$I12=9),IF($K12="","Long fast month","Long fast month (LEAP)"),"")) | K12: =IFERROR(IF(INDEX(lookup!$G:$G,MATCH($C12,lookup!$D:$D,0))="LEAP","LEAP MONTH - counts as month "&$I12&", flagged for review",""),"")
A13: =A12+1 | B13: =TEXT(A13,"ddd") | C13: =IF($E13=1,"?",C12) | D13: 十一 | E13: {=_xlfn.XLOOKUP($D13,lookup!$A:$A,lookup!$B:$B)} | G13: Celebration of Ullambana (Observed) | H13: =IF($E13="","",IF(OR($E13=8,$E13=14,$E13=15,$E13=23,$E14=1,$E15=1),"Fast day","")) | I13: =IFERROR(INDEX(lookup!$E:$E,MATCH($C13,lookup!$D:$D,0)),"") | J13: =IF($I13="","",IF(OR($I13=1,$I13=5,$I13=9),IF($K13="","Long fast month","Long fast month (LEAP)"),"")) | K13: =IFERROR(IF(INDEX(lookup!$G:$G,MATCH($C13,lookup!$D:$D,0))="LEAP","LEAP MONTH - counts as month "&$I13&", flagged for review",""),"")
A14: =A13+1 | B14: =TEXT(A14,"ddd") | C14: =IF($E14=1,"?",C13) | D14: 十二 | E14: {=_xlfn.XLOOKUP($D14,lookup!$A:$A,lookup!$B:$B)} | H14: =IF($E14="","",IF(OR($E14=8,$E14=14,$E14=15,$E14=23,$E15=1,$E16=1),"Fast day","")) | I14: =IFERROR(INDEX(lookup!$E:$E,MATCH($C14,lookup!$D:$D,0)),"") | J14: =IF($I14="","",IF(OR($I14=1,$I14=5,$I14=9),IF($K14="","Long fast month","Long fast month (LEAP)"),"")) | K14: =IFERROR(IF(INDEX(lookup!$G:$G,MATCH($C14,lookup!$D:$D,0))="LEAP","LEAP MONTH - counts as month "&$I14&", flagged for review",""),"")
A15: =A14+1 | B15: =TEXT(A15,"ddd") | C15: =IF($E15=1,"?",C14) | D15: 十三 | E15: {=_xlfn.XLOOKUP($D15,lookup!$A:$A,lookup!$B:$B)} | G15: Great Strength Bodhisattva’s Birthday | H15: =IF($E15="","",IF(OR($E15=8,$E15=14,$E15=15,$E15=23,$E16=1,$E17=1),"Fast day","")) | I15: =IFERROR(INDEX(lookup!$E:$E,MATCH($C15,lookup!$D:$D,0)),"") | J15: =IF($I15="","",IF(OR($I15=1,$I15=5,$I15=9),IF($K15="","Long fast month","Long fast month (LEAP)"),"")) | K15: =IFERROR(IF(INDEX(lookup!$G:$G,MATCH($C15,lookup!$D:$D,0))="LEAP","LEAP MONTH - counts as month "&$I15&", flagged for review",""),"")
A16: =A15+1 | B16: =TEXT(A16,"ddd") | C16: =IF($E16=1,"?",C15) | D16: 十四 | E16: {=_xlfn.XLOOKUP($D16,lookup!$A:$A,lookup!$B:$B)} | H16: =IF($E16="","",IF(OR($E16=8,$E16=14,$E16=15,$E16=23,$E17=1,$E18=1),"Fast day","")) | I16: =IFERROR(INDEX(lookup!$E:$E,MATCH($C16,lookup!$D:$D,0)),"") | J16: =IF($I16="","",IF(OR($I16=1,$I16=5,$I16=9),IF($K16="","Long fast month","Long fast month (LEAP)"),"")) | K16: =IFERROR(IF(INDEX(lookup!$G:$G,MATCH($C16,lookup!$D:$D,0))="LEAP","LEAP MONTH - counts as month "&$I16&", flagged for review",""),"")
A17: =A16+1 | B17: =TEXT(A17,"ddd") | C17: 七月 | D17: 十五 | E17: {=_xlfn.XLOOKUP($D17,lookup!$A:$A,lookup!$B:$B)} | F17: Full | G17: Ullambana (actual day) | H17: =IF($E17="","",IF(OR($E17=8,$E17=14,$E17=15,$E17=23,$E18=1,$E19=1),"Fast day","")) | I17: =IFERROR(INDEX(lookup!$E:$E,MATCH($C17,lookup!$D:$D,0)),"") | J17: =IF($I17="","",IF(OR($I17=1,$I17=5,$I17=9),IF($K17="","Long fast month","Long fast month (LEAP)"),"")) | K17: =IFERROR(IF(INDEX(lookup!$G:$G,MATCH($C17,lookup!$D:$D,0))="LEAP","LEAP MONTH - counts as month "&$I17&", flagged for review",""),"")
A18: =A17+1 | B18: =TEXT(A18,"ddd") | C18: =IF($E18=1,"?",C17) | D18: 十六 | E18: {=_xlfn.XLOOKUP($D18,lookup!$A:$A,lookup!$B:$B)} | H18: =IF($E18="","",IF(OR($E18=8,$E18=14,$E18=15,$E18=23,$E19=1,$E20=1),"Fast day","")) | I18: =IFERROR(INDEX(lookup!$E:$E,MATCH($C18,lookup!$D:$D,0)),"") | J18: =IF($I18="","",IF(OR($I18=1,$I18=5,$I18=9),IF($K18="","Long fast month","Long fast month (LEAP)"),"")) | K18: =IFERROR(IF(INDEX(lookup!$G:$G,MATCH($C18,lookup!$D:$D,0))="LEAP","LEAP MONTH - counts as month "&$I18&", flagged for review",""),"")
A19: =A18+1 | B19: =TEXT(A19,"ddd") | C19: =IF($E19=1,"?",C18) | D19: 十七 | E19: {=_xlfn.XLOOKUP($D19,lookup!$A:$A,lookup!$B:$B)} | H19: =IF($E19="","",IF(OR($E19=8,$E19=14,$E19=15,$E19=23,$E20=1,$E21=1),"Fast day","")) | I19: =IFERROR(INDEX(lookup!$E:$E,MATCH($C19,lookup!$D:$D,0)),"") | J19: =IF($I19="","",IF(OR($I19=1,$I19=5,$I19=9),IF($K19="","Long fast month","Long fast month (LEAP)"),"")) | K19: =IFERROR(IF(INDEX(lookup!$G:$G,MATCH($C19,lookup!$D:$D,0))="LEAP","LEAP MONTH - counts as month "&$I19&", flagged for review",""),"")
A20: =A19+1 | B20: =TEXT(A20,"ddd") | C20: =IF($E20=1,"?",C19) | D20: 十八 | E20: {=_xlfn.XLOOKUP($D20,lookup!$A:$A,lookup!$B:$B)} | H20: =IF($E20="","",IF(OR($E20=8,$E20=14,$E20=15,$E20=23,$E21=1,$E22=1),"Fast day","")) | I20: =IFERROR(INDEX(lookup!$E:$E,MATCH($C20,lookup!$D:$D,0)),"") | J20: =IF($I20="","",IF(OR($I20=1,$I20=5,$I20=9),IF($K20="","Long fast month","Long fast month (LEAP)"),"")) | K20: =IFERROR(IF(INDEX(lookup!$G:$G,MATCH($C20,lookup!$D:$D,0))="LEAP","LEAP MONTH - counts as month "&$I20&", flagged for review",""),"")
A21: =A20+1 | B21: =TEXT(A21,"ddd") | C21: =IF($E21=1,"?",C20) | D21: 十九 | E21: {=_xlfn.XLOOKUP($D21,lookup!$A:$A,lookup!$B:$B)} | H21: =IF($E21="","",IF(OR($E21=8,$E21=14,$E21=15,$E21=23,$E22=1,$E23=1),"Fast day","")) | I21: =IFERROR(INDEX(lookup!$E:$E,MATCH($C21,lookup!$D:$D,0)),"") | J21: =IF($I21="","",IF(OR($I21=1,$I21=5,$I21=9),IF($K21="","Long fast month","Long fast month (LEAP)"),"")) | K21: =IFERROR(IF(INDEX(lookup!$G:$G,MATCH($C21,lookup!$D:$D,0))="LEAP","LEAP MONTH - counts as month "&$I21&", flagged for review",""),"")
A22: =A21+1 | B22: =TEXT(A22,"ddd") | C22: =IF($E22=1,"?",C21) | D22: 二十 | E22: {=_xlfn.XLOOKUP($D22,lookup!$A:$A,lookup!$B:$B)} | H22: =IF($E22="","",IF(OR($E22=8,$E22=14,$E22=15,$E22=23,$E23=1,$E24=1),"Fast day","")) | I22: =IFERROR(INDEX(lookup!$E:$E,MATCH($C22,lookup!$D:$D,0)),"") | J22: =IF($I22="","",IF(OR($I22=1,$I22=5,$I22=9),IF($K22="","Long fast month","Long fast month (LEAP)"),"")) | K22: =IFERROR(IF(INDEX(lookup!$G:$G,MATCH($C22,lookup!$D:$D,0))="LEAP","LEAP MONTH - counts as month "&$I22&", flagged for review",""),"")
A23: =A22+1 | B23: =TEXT(A23,"ddd") | C23: =IF($E23=1,"?",C22) | D23: 廿一 | E23: {=_xlfn.XLOOKUP($D23,lookup!$A:$A,lookup!$B:$B)} | G23: Patriarch Pu An’s Birthday | H23: =IF($E23="","",IF(OR($E23=8,$E23=14,$E23=15,$E23=23,$E24=1,$E25=1),"Fast day","")) | I23: =IFERROR(INDEX(lookup!$E:$E,MATCH($C23,lookup!$D:$D,0)),"") | J23: =IF($I23="","",IF(OR($I23=1,$I23=5,$I23=9),IF($K23="","Long fast month","Long fast month (LEAP)"),"")) | K23: =IFERROR(IF(INDEX(lookup!$G:$G,MATCH($C23,lookup!$D:$D,0))="LEAP","LEAP MONTH - counts as month "&$I23&", flagged for review",""),"")
A24: =A23+1 | B24: =TEXT(A24,"ddd") | C24: =IF($E24=1,"?",C23) | D24: 廿二 | E24: {=_xlfn.XLOOKUP($D24,lookup!$A:$A,lookup!$B:$B)} | H24: =IF($E24="","",IF(OR($E24=8,$E24=14,$E24=15,$E24=23,$E25=1,$E26=1),"Fast day","")) | I24: =IFERROR(INDEX(lookup!$E:$E,MATCH($C24,lookup!$D:$D,0)),"") | J24: =IF($I24="","",IF(OR($I24=1,$I24=5,$I24=9),IF($K24="","Long fast month","Long fast month (LEAP)"),"")) | K24: =IFERROR(IF(INDEX(lookup!$G:$G,MATCH($C24,lookup!$D:$D,0))="LEAP","LEAP MONTH - counts as month "&$I24&", flagged for review",""),"")
A25: =A24+1 | B25: =TEXT(A25,"ddd") | C25: =IF($E25=1,"?",C24) | D25: 廿三 | E25: {=_xlfn.XLOOKUP($D25,lookup!$A:$A,lookup!$B:$B)} | H25: =IF($E25="","",IF(OR($E25=8,$E25=14,$E25=15,$E25=23,$E26=1,$E27=1),"Fast day","")) | I25: =IFERROR(INDEX(lookup!$E:$E,MATCH($C25,lookup!$D:$D,0)),"") | J25: =IF($I25="","",IF(OR($I25=1,$I25=5,$I25=9),IF($K25="","Long fast month","Long fast month (LEAP)"),"")) | K25: =IFERROR(IF(INDEX(lookup!$G:$G,MATCH($C25,lookup!$D:$D,0))="LEAP","LEAP MONTH - counts as month "&$I25&", flagged for review",""),"")
A26: =A25+1 | B26: =TEXT(A26,"ddd") | C26: =IF($E26=1,"?",C25) | D26: 廿四 | E26: {=_xlfn.XLOOKUP($D26,lookup!$A:$A,lookup!$B:$B)} | G26: Nagarjuna Bodhisattva’s Birthday | H26: =IF($E26="","",IF(OR($E26=8,$E26=14,$E26=15,$E26=23,$E27=1,$E28=1),"Fast day","")) | I26: =IFERROR(INDEX(lookup!$E:$E,MATCH($C26,lookup!$D:$D,0)),"") | J26: =IF($I26="","",IF(OR($I26=1,$I26=5,$I26=9),IF($K26="","Long fast month","Long fast month (LEAP)"),"")) | K26: =IFERROR(IF(INDEX(lookup!$G:$G,MATCH($C26,lookup!$D:$D,0))="LEAP","LEAP MONTH - counts as month "&$I26&", flagged for review",""),"")
A27: =A26+1 | B27: =TEXT(A27,"ddd") | C27: =IF($E27=1,"?",C26) | D27: 廿五 | E27: {=_xlfn.XLOOKUP($D27,lookup!$A:$A,lookup!$B:$B)} | G27: Celebration of Earth Store Bodhisattva’s Birthday (Observed) | H27: =IF($E27="","",IF(OR($E27=8,$E27=14,$E27=15,$E27=23,$E28=1,$E29=1),"Fast day","")) | I27: =IFERROR(INDEX(lookup!$E:$E,MATCH($C27,lookup!$D:$D,0)),"") | J27: =IF($I27="","",IF(OR($I27=1,$I27=5,$I27=9),IF($K27="","Long fast month","Long fast month (LEAP)"),"")) | K27: =IFERROR(IF(INDEX(lookup!$G:$G,MATCH($C27,lookup!$D:$D,0))="LEAP","LEAP MONTH - counts as month "&$I27&", flagged for review",""),"")
A28: =A27+1 | B28: =TEXT(A28,"ddd") | C28: =IF($E28=1,"?",C27) | D28: 廿六 | E28: {=_xlfn.XLOOKUP($D28,lookup!$A:$A,lookup!$B:$B)} | G28: Labor Day (no school) | H28: =IF($E28="","",IF(OR($E28=8,$E28=14,$E28=15,$E28=23,$E29=1,$E30=1),"Fast day","")) | I28: =IFERROR(INDEX(lookup!$E:$E,MATCH($C28,lookup!$D:$D,0)),"") | J28: =IF($I28="","",IF(OR($I28=1,$I28=5,$I28=9),IF($K28="","Long fast month","Long fast month (LEAP)"),"")) | K28: =IFERROR(IF(INDEX(lookup!$G:$G,MATCH($C28,lookup!$D:$D,0))="LEAP","LEAP MONTH - counts as month "&$I28&", flagged for review",""),"")
A29: =A28+1 | B29: =TEXT(A29,"ddd") | C29: =IF($E29=1,"?",C28) | D29: 廿七 | E29: {=_xlfn.XLOOKUP($D29,lookup!$A:$A,lookup!$B:$B)} | H29: =IF($E29="","",IF(OR($E29=8,$E29=14,$E29=15,$E29=23,$E30=1,$E31=1),"Fast day","")) | I29: =IFERROR(INDEX(lookup!$E:$E,MATCH($C29,lookup!$D:$D,0)),"") | J29: =IF($I29="","",IF(OR($I29=1,$I29=5,$I29=9),IF($K29="","Long fast month","Long fast month (LEAP)"),"")) | K29: =IFERROR(IF(INDEX(lookup!$G:$G,MATCH($C29,lookup!$D:$D,0))="LEAP","LEAP MONTH - counts as month "&$I29&", flagged for review",""),"")
A30: =A29+1 | B30: =TEXT(A30,"ddd") | C30: =IF($E30=1,"?",C29) | D30: 廿八 | E30: {=_xlfn.XLOOKUP($D30,lookup!$A:$A,lookup!$B:$B)} | H30: =IF($E30="","",IF(OR($E30=8,$E30=14,$E30=15,$E30=23,$E31=1,$E32=1),"Fast day","")) | I30: =IFERROR(INDEX(lookup!$E:$E,MATCH($C30,lookup!$D:$D,0)),"") | J30: =IF($I30="","",IF(OR($I30=1,$I30=5,$I30=9),IF($K30="","Long fast month","Long fast month (LEAP)"),"")) | K30: =IFERROR(IF(INDEX(lookup!$G:$G,MATCH($C30,lookup!$D:$D,0))="LEAP","LEAP MONTH - counts as month "&$I30&", flagged for review",""),"")
A31: =A30+1 | B31: =TEXT(A31,"ddd") | C31: =IF($E31=1,"?",C30) | D31: 廿九 | E31: {=_xlfn.XLOOKUP($D31,lookup!$A:$A,lookup!$B:$B)} | G31: Earth Store Bodhisattva’s Birthday ( actual day ) | Venerable Master Hsu Yun’s Birthday | H31: =IF($E31="","",IF(OR($E31=8,$E31=14,$E31=15,$E31=23,$E32=1,$E33=1),"Fast day","")) | I31: =IFERROR(INDEX(lookup!$E:$E,MATCH($C31,lookup!$D:$D,0)),"") | J31: =IF($I31="","",IF(OR($I31=1,$I31=5,$I31=9),IF($K31="","Long fast month","Long fast month (LEAP)"),"")) | K31: =IFERROR(IF(INDEX(lookup!$G:$G,MATCH($C31,lookup!$D:$D,0))="LEAP","LEAP MONTH - counts as month "&$I31&", flagged for review",""),"")
A32: =A31+1 | B32: =TEXT(A32,"ddd") | C32: 八月 | D32: 初一 | E32: {=_xlfn.XLOOKUP($D32,lookup!$A:$A,lookup!$B:$B)} | F32: New | H32: =IF($E32="","",IF(OR($E32=8,$E32=14,$E32=15,$E32=23,$E33=1,$E34=1),"Fast day","")) | I32: =IFERROR(INDEX(lookup!$E:$E,MATCH($C32,lookup!$D:$D,0)),"") | J32: =IF($I32="","",IF(OR($I32=1,$I32=5,$I32=9),IF($K32="","Long fast month","Long fast month (LEAP)"),"")) | K32: =IFERROR(IF(INDEX(lookup!$G:$G,MATCH($C32,lookup!$D:$D,0))="LEAP","LEAP MONTH - counts as month "&$I32&", flagged for review",""),"")
A33: =A32+1 | B33: =TEXT(A33,"ddd") | C33: =IF($E33=1,"?",C32) | D33: 初二 | E33: {=_xlfn.XLOOKUP($D33,lookup!$A:$A,lookup!$B:$B)} | H33: =IF($E33="","",IF(OR($E33=8,$E33=14,$E33=15,$E33=23,$E34=1,$E35=1),"Fast day","")) | I33: =IFERROR(INDEX(lookup!$E:$E,MATCH($C33,lookup!$D:$D,0)),"") | J33: =IF($I33="","",IF(OR($I33=1,$I33=5,$I33=9),IF($K33="","Long fast month","Long fast month (LEAP)"),"")) | K33: =IFERROR(IF(INDEX(lookup!$G:$G,MATCH($C33,lookup!$D:$D,0))="LEAP","LEAP MONTH - counts as month "&$I33&", flagged for review",""),"")
A34: =A33+1 | B34: =TEXT(A34,"ddd") | C34: =IF($E34=1,"?",C33) | D34: 初三 | E34: {=_xlfn.XLOOKUP($D34,lookup!$A:$A,lookup!$B:$B)} | G34: Venerable Sixth Patriarch’s Nirvana Day | H34: =IF($E34="","",IF(OR($E34=8,$E34=14,$E34=15,$E34=23,$E35=1,$E36=1),"Fast day","")) | I34: =IFERROR(INDEX(lookup!$E:$E,MATCH($C34,lookup!$D:$D,0)),"") | J34: =IF($I34="","",IF(OR($I34=1,$I34=5,$I34=9),IF($K34="","Long fast month","Long fast month (LEAP)"),"")) | K34: =IFERROR(IF(INDEX(lookup!$G:$G,MATCH($C34,lookup!$D:$D,0))="LEAP","LEAP MONTH - counts as month "&$I34&", flagged for review",""),"")
A35: =A34+1 | B35: =TEXT(A35,"ddd") | C35: =IF($E35=1,"?",C34) | D35: 初四 | E35: {=_xlfn.XLOOKUP($D35,lookup!$A:$A,lookup!$B:$B)} | H35: =IF($E35="","",IF(OR($E35=8,$E35=14,$E35=15,$E35=23,$E36=1,$E37=1),"Fast day","")) | I35: =IFERROR(INDEX(lookup!$E:$E,MATCH($C35,lookup!$D:$D,0)),"") | J35: =IF($I35="","",IF(OR($I35=1,$I35=5,$I35=9),IF($K35="","Long fast month","Long fast month (LEAP)"),"")) | K35: =IFERROR(IF(INDEX(lookup!$G:$G,MATCH($C35,lookup!$D:$D,0))="LEAP","LEAP MONTH - counts as month "&$I35&", flagged for review",""),"")
A36: =A35+1 | B36: =TEXT(A36,"ddd") | C36: =IF($E36=1,"?",C35) | D36: 初五 | E36: {=_xlfn.XLOOKUP($D36,lookup!$A:$A,lookup!$B:$B)} | H36: =IF($E36="","",IF(OR($E36=8,$E36=14,$E36=15,$E36=23,$E37=1,$E38=1),"Fast day","")) | I36: =IFERROR(INDEX(lookup!$E:$E,MATCH($C36,lookup!$D:$D,0)),"") | J36: =IF($I36="","",IF(OR($I36=1,$I36=5,$I36=9),IF($K36="","Long fast month","Long fast month (LEAP)"),"")) | K36: =IFERROR(IF(INDEX(lookup!$G:$G,MATCH($C36,lookup!$D:$D,0))="LEAP","LEAP MONTH - counts as month "&$I36&", flagged for review",""),"")
A37: =A36+1 | B37: =TEXT(A37,"ddd") | C37: =IF($E37=1,"?",C36) | D37: 初六 | E37: {=_xlfn.XLOOKUP($D37,lookup!$A:$A,lookup!$B:$B)} | H37: =IF($E37="","",IF(OR($E37=8,$E37=14,$E37=15,$E37=23,$E38=1,$E39=1),"Fast day","")) | I37: =IFERROR(INDEX(lookup!$E:$E,MATCH($C37,lookup!$D:$D,0)),"") | J37: =IF($I37="","",IF(OR($I37=1,$I37=5,$I37=9),IF($K37="","Long fast month","Long fast month (LEAP)"),"")) | K37: =IFERROR(IF(INDEX(lookup!$G:$G,MATCH($C37,lookup!$D:$D,0))="LEAP","LEAP MONTH - counts as month "&$I37&", flagged for review",""),"")
A38: =A37+1 | B38: =TEXT(A38,"ddd") | C38: =IF($E38=1,"?",C37) | D38: 初七 | E38: {=_xlfn.XLOOKUP($D38,lookup!$A:$A,lookup!$B:$B)} | H38: =IF($E38="","",IF(OR($E38=8,$E38=14,$E38=15,$E38=23,$E39=1,$E40=1),"Fast day","")) | I38: =IFERROR(INDEX(lookup!$E:$E,MATCH($C38,lookup!$D:$D,0)),"") | J38: =IF($I38="","",IF(OR($I38=1,$I38=5,$I38=9),IF($K38="","Long fast month","Long fast month (LEAP)"),"")) | K38: =IFERROR(IF(INDEX(lookup!$G:$G,MATCH($C38,lookup!$D:$D,0))="LEAP","LEAP MONTH - counts as month "&$I38&", flagged for review",""),"")
A39: =A38+1 | B39: =TEXT(A39,"ddd") | C39: =IF($E39=1,"?",C38) | D39: 初八 | E39: {=_xlfn.XLOOKUP($D39,lookup!$A:$A,lookup!$B:$B)} | H39: =IF($E39="","",IF(OR($E39=8,$E39=14,$E39=15,$E39=23,$E40=1,$E41=1),"Fast day","")) | I39: =IFERROR(INDEX(lookup!$E:$E,MATCH($C39,lookup!$D:$D,0)),"") | J39: =IF($I39="","",IF(OR($I39=1,$I39=5,$I39=9),IF($K39="","Long fast month","Long fast month (LEAP)"),"")) | K39: =IFERROR(IF(INDEX(lookup!$G:$G,MATCH($C39,lookup!$D:$D,0))="LEAP","LEAP MONTH - counts as month "&$I39&", flagged for review",""),"")
A40: =A39+1 | B40: =TEXT(A40,"ddd") | C40: =IF($E40=1,"?",C39) | D40: 初九 | E40: {=_xlfn.XLOOKUP($D40,lookup!$A:$A,lookup!$B:$B)} | H40: =IF($E40="","",IF(OR($E40=8,$E40=14,$E40=15,$E40=23,$E41=1,$E42=1),"Fast day","")) | I40: =IFERROR(INDEX(lookup!$E:$E,MATCH($C40,lookup!$D:$D,0)),"") | J40: =IF($I40="","",IF(OR($I40=1,$I40=5,$I40=9),IF($K40="","Long fast month","Long fast month (LEAP)"),"")) | K40: =IFERROR(IF(INDEX(lookup!$G:$G,MATCH($C40,lookup!$D:$D,0))="LEAP","LEAP MONTH - counts as month "&$I40&", flagged for review",""),"")
...

Sheet hko_extended
A1: date | B1: weekday | C1: lunar_month | D1: lunar_day | E1: lunar_day_eng | F1: moon_phase | G1: dharma_event | H1: 六齋日 | I1: lunar_month_eng | J1: 三長齋月 | K1: leap_month
A2: =drba!A174+1 | B2: =TEXT(A2,"ddd") | C2: =IFERROR(INDEX(lunar_ref!$B:$B,MATCH($A2,lunar_ref!$A:$A,0)),"") | D2: =IFERROR(INDEX(lunar_ref!$C:$C,MATCH($A2,lunar_ref!$A:$A,0)),"") | E2: =_xlfn.XLOOKUP($D2,lookup!$A:$A,lookup!$B:$B) | F2: =IF($E2=1,"New",IF($E2=15,"Full","")) | H2: =IF($E2="","",IF(OR($E2=8,$E2=14,$E2=15,$E2=23,$E3=1,$E4=1),"Fast day","")) | I2: =IFERROR(INDEX(lookup!$E:$E,MATCH($C2,lookup!$D:$D,0)),"") | J2: =IF($I2="","",IF(OR($I2=1,$I2=5,$I2=9),IF($K2="","Long fast month","Long fast month (LEAP)"),"")) | K2: =IFERROR(IF(INDEX(lookup!$G:$G,MATCH($C2,lookup!$D:$D,0))="LEAP","LEAP MONTH - counts as month "&$I2&", flagged for review",""),"")
A3: =A2+1 | B3: =TEXT(A3,"ddd") | C3: =IFERROR(INDEX(lunar_ref!$B:$B,MATCH($A3,lunar_ref!$A:$A,0)),"") | D3: =IFERROR(INDEX(lunar_ref!$C:$C,MATCH($A3,lunar_ref!$A:$A,0)),"") | E3: =_xlfn.XLOOKUP($D3,lookup!$A:$A,lookup!$B:$B) | F3: =IF($E3=1,"New",IF($E3=15,"Full","")) | H3: =IF($E3="","",IF(OR($E3=8,$E3=14,$E3=15,$E3=23,$E4=1,$E5=1),"Fast day","")) | I3: =IFERROR(INDEX(lookup!$E:$E,MATCH($C3,lookup!$D:$D,0)),"") | J3: =IF($I3="","",IF(OR($I3=1,$I3=5,$I3=9),IF($K3="","Long fast month","Long fast month (LEAP)"),"")) | K3: =IFERROR(IF(INDEX(lookup!$G:$G,MATCH($C3,lookup!$D:$D,0))="LEAP","LEAP MONTH - counts as month "&$I3&", flagged for review",""),"")
A4: =A3+1 | B4: =TEXT(A4,"ddd") | C4: =IFERROR(INDEX(lunar_ref!$B:$B,MATCH($A4,lunar_ref!$A:$A,0)),"") | D4: =IFERROR(INDEX(lunar_ref!$C:$C,MATCH($A4,lunar_ref!$A:$A,0)),"") | E4: =_xlfn.XLOOKUP($D4,lookup!$A:$A,lookup!$B:$B) | F4: =IF($E4=1,"New",IF($E4=15,"Full","")) | H4: =IF($E4="","",IF(OR($E4=8,$E4=14,$E4=15,$E4=23,$E5=1,$E6=1),"Fast day","")) | I4: =IFERROR(INDEX(lookup!$E:$E,MATCH($C4,lookup!$D:$D,0)),"") | J4: =IF($I4="","",IF(OR($I4=1,$I4=5,$I4=9),IF($K4="","Long fast month","Long fast month (LEAP)"),"")) | K4: =IFERROR(IF(INDEX(lookup!$G:$G,MATCH($C4,lookup!$D:$D,0))="LEAP","LEAP MONTH - counts as month "&$I4&", flagged for review",""),"")
A5: =A4+1 | B5: =TEXT(A5,"ddd") | C5: =IFERROR(INDEX(lunar_ref!$B:$B,MATCH($A5,lunar_ref!$A:$A,0)),"") | D5: =IFERROR(INDEX(lunar_ref!$C:$C,MATCH($A5,lunar_ref!$A:$A,0)),"") | E5: =_xlfn.XLOOKUP($D5,lookup!$A:$A,lookup!$B:$B) | F5: =IF($E5=1,"New",IF($E5=15,"Full","")) | H5: =IF($E5="","",IF(OR($E5=8,$E5=14,$E5=15,$E5=23,$E6=1,$E7=1),"Fast day","")) | I5: =IFERROR(INDEX(lookup!$E:$E,MATCH($C5,lookup!$D:$D,0)),"") | J5: =IF($I5="","",IF(OR($I5=1,$I5=5,$I5=9),IF($K5="","Long fast month","Long fast month (LEAP)"),"")) | K5: =IFERROR(IF(INDEX(lookup!$G:$G,MATCH($C5,lookup!$D:$D,0))="LEAP","LEAP MONTH - counts as month "&$I5&", flagged for review",""),"")
A6: =A5+1 | B6: =TEXT(A6,"ddd") | C6: =IFERROR(INDEX(lunar_ref!$B:$B,MATCH($A6,lunar_ref!$A:$A,0)),"") | D6: =IFERROR(INDEX(lunar_ref!$C:$C,MATCH($A6,lunar_ref!$A:$A,0)),"") | E6: =_xlfn.XLOOKUP($D6,lookup!$A:$A,lookup!$B:$B) | F6: =IF($E6=1,"New",IF($E6=15,"Full","")) | H6: =IF($E6="","",IF(OR($E6=8,$E6=14,$E6=15,$E6=23,$E7=1,$E8=1),"Fast day","")) | I6: =IFERROR(INDEX(lookup!$E:$E,MATCH($C6,lookup!$D:$D,0)),"") | J6: =IF($I6="","",IF(OR($I6=1,$I6=5,$I6=9),IF($K6="","Long fast month","Long fast month (LEAP)"),"")) | K6: =IFERROR(IF(INDEX(lookup!$G:$G,MATCH($C6,lookup!$D:$D,0))="LEAP","LEAP MONTH - counts as month "&$I6&", flagged for review",""),"")
A7: =A6+1 | B7: =TEXT(A7,"ddd") | C7: =IFERROR(INDEX(lunar_ref!$B:$B,MATCH($A7,lunar_ref!$A:$A,0)),"") | D7: =IFERROR(INDEX(lunar_ref!$C:$C,MATCH($A7,lunar_ref!$A:$A,0)),"") | E7: =_xlfn.XLOOKUP($D7,lookup!$A:$A,lookup!$B:$B) | F7: =IF($E7=1,"New",IF($E7=15,"Full","")) | H7: =IF($E7="","",IF(OR($E7=8,$E7=14,$E7=15,$E7=23,$E8=1,$E9=1),"Fast day","")) | I7: =IFERROR(INDEX(lookup!$E:$E,MATCH($C7,lookup!$D:$D,0)),"") | J7: =IF($I7="","",IF(OR($I7=1,$I7=5,$I7=9),IF($K7="","Long fast month","Long fast month (LEAP)"),"")) | K7: =IFERROR(IF(INDEX(lookup!$G:$G,MATCH($C7,lookup!$D:$D,0))="LEAP","LEAP MONTH - counts as month "&$I7&", flagged for review",""),"")
A8: =A7+1 | B8: =TEXT(A8,"ddd") | C8: =IFERROR(INDEX(lunar_ref!$B:$B,MATCH($A8,lunar_ref!$A:$A,0)),"") | D8: =IFERROR(INDEX(lunar_ref!$C:$C,MATCH($A8,lunar_ref!$A:$A,0)),"") | E8: =_xlfn.XLOOKUP($D8,lookup!$A:$A,lookup!$B:$B) | F8: =IF($E8=1,"New",IF($E8=15,"Full","")) | H8: =IF($E8="","",IF(OR($E8=8,$E8=14,$E8=15,$E8=23,$E9=1,$E10=1),"Fast day","")) | I8: =IFERROR(INDEX(lookup!$E:$E,MATCH($C8,lookup!$D:$D,0)),"") | J8: =IF($I8="","",IF(OR($I8=1,$I8=5,$I8=9),IF($K8="","Long fast month","Long fast month (LEAP)"),"")) | K8: =IFERROR(IF(INDEX(lookup!$G:$G,MATCH($C8,lookup!$D:$D,0))="LEAP","LEAP MONTH - counts as month "&$I8&", flagged for review",""),"")
A9: =A8+1 | B9: =TEXT(A9,"ddd") | C9: =IFERROR(INDEX(lunar_ref!$B:$B,MATCH($A9,lunar_ref!$A:$A,0)),"") | D9: =IFERROR(INDEX(lunar_ref!$C:$C,MATCH($A9,lunar_ref!$A:$A,0)),"") | E9: =_xlfn.XLOOKUP($D9,lookup!$A:$A,lookup!$B:$B) | F9: =IF($E9=1,"New",IF($E9=15,"Full","")) | H9: =IF($E9="","",IF(OR($E9=8,$E9=14,$E9=15,$E9=23,$E10=1,$E11=1),"Fast day","")) | I9: =IFERROR(INDEX(lookup!$E:$E,MATCH($C9,lookup!$D:$D,0)),"") | J9: =IF($I9="","",IF(OR($I9=1,$I9=5,$I9=9),IF($K9="","Long fast month","Long fast month (LEAP)"),"")) | K9: =IFERROR(IF(INDEX(lookup!$G:$G,MATCH($C9,lookup!$D:$D,0))="LEAP","LEAP MONTH - counts as month "&$I9&", flagged for review",""),"")
A10: =A9+1 | B10: =TEXT(A10,"ddd") | C10: =IFERROR(INDEX(lunar_ref!$B:$B,MATCH($A10,lunar_ref!$A:$A,0)),"") | D10: =IFERROR(INDEX(lunar_ref!$C:$C,MATCH($A10,lunar_ref!$A:$A,0)),"") | E10: =_xlfn.XLOOKUP($D10,lookup!$A:$A,lookup!$B:$B) | F10: =IF($E10=1,"New",IF($E10=15,"Full","")) | H10: =IF($E10="","",IF(OR($E10=8,$E10=14,$E10=15,$E10=23,$E11=1,$E12=1),"Fast day","")) | I10: =IFERROR(INDEX(lookup!$E:$E,MATCH($C10,lookup!$D:$D,0)),"") | J10: =IF($I10="","",IF(OR($I10=1,$I10=5,$I10=9),IF($K10="","Long fast month","Long fast month (LEAP)"),"")) | K10: =IFERROR(IF(INDEX(lookup!$G:$G,MATCH($C10,lookup!$D:$D,0))="LEAP","LEAP MONTH - counts as month "&$I10&", flagged for review",""),"")
A11: =A10+1 | B11: =TEXT(A11,"ddd") | C11: =IFERROR(INDEX(lunar_ref!$B:$B,MATCH($A11,lunar_ref!$A:$A,0)),"") | D11: =IFERROR(INDEX(lunar_ref!$C:$C,MATCH($A11,lunar_ref!$A:$A,0)),"") | E11: =_xlfn.XLOOKUP($D11,lookup!$A:$A,lookup!$B:$B) | F11: =IF($E11=1,"New",IF($E11=15,"Full","")) | H11: =IF($E11="","",IF(OR($E11=8,$E11=14,$E11=15,$E11=23,$E12=1,$E13=1),"Fast day","")) | I11: =IFERROR(INDEX(lookup!$E:$E,MATCH($C11,lookup!$D:$D,0)),"") | J11: =IF($I11="","",IF(OR($I11=1,$I11=5,$I11=9),IF($K11="","Long fast month","Long fast month (LEAP)"),"")) | K11: =IFERROR(IF(INDEX(lookup!$G:$G,MATCH($C11,lookup!$D:$D,0))="LEAP","LEAP MONTH - counts as month "&$I11&", flagged for review",""),"")
A12: =A11+1 | B12: =TEXT(A12,"ddd") | C12: =IFERROR(INDEX(lunar_ref!$B:$B,MATCH($A12,lunar_ref!$A:$A,0)),"") | D12: =IFERROR(INDEX(lunar_ref!$C:$C,MATCH($A12,lunar_ref!$A:$A,0)),"") | E12: =_xlfn.XLOOKUP($D12,lookup!$A:$A,lookup!$B:$B) | F12: =IF($E12=1,"New",IF($E12=15,"Full","")) | H12: =IF($E12="","",IF(OR($E12=8,$E12=14,$E12=15,$E12=23,$E13=1,$E14=1),"Fast day","")) | I12: =IFERROR(INDEX(lookup!$E:$E,MATCH($C12,lookup!$D:$D,0)),"") | J12: =IF($I12="","",IF(OR($I12=1,$I12=5,$I12=9),IF($K12="","Long fast month","Long fast month (LEAP)"),"")) | K12: =IFERROR(IF(INDEX(lookup!$G:$G,MATCH($C12,lookup!$D:$D,0))="LEAP","LEAP MONTH - counts as month "&$I12&", flagged for review",""),"")
A13: =A12+1 | B13: =TEXT(A13,"ddd") | C13: =IFERROR(INDEX(lunar_ref!$B:$B,MATCH($A13,lunar_ref!$A:$A,0)),"") | D13: =IFERROR(INDEX(lunar_ref!$C:$C,MATCH($A13,lunar_ref!$A:$A,0)),"") | E13: =_xlfn.XLOOKUP($D13,lookup!$A:$A,lookup!$B:$B) | F13: =IF($E13=1,"New",IF($E13=15,"Full","")) | H13: =IF($E13="","",IF(OR($E13=8,$E13=14,$E13=15,$E13=23,$E14=1,$E15=1),"Fast day","")) | I13: =IFERROR(INDEX(lookup!$E:$E,MATCH($C13,lookup!$D:$D,0)),"") | J13: =IF($I13="","",IF(OR($I13=1,$I13=5,$I13=9),IF($K13="","Long fast month","Long fast month (LEAP)"),"")) | K13: =IFERROR(IF(INDEX(lookup!$G:$G,MATCH($C13,lookup!$D:$D,0))="LEAP","LEAP MONTH - counts as month "&$I13&", flagged for review",""),"")
A14: =A13+1 | B14: =TEXT(A14,"ddd") | C14: =IFERROR(INDEX(lunar_ref!$B:$B,MATCH($A14,lunar_ref!$A:$A,0)),"") | D14: =IFERROR(INDEX(lunar_ref!$C:$C,MATCH($A14,lunar_ref!$A:$A,0)),"") | E14: =_xlfn.XLOOKUP($D14,lookup!$A:$A,lookup!$B:$B) | F14: =IF($E14=1,"New",IF($E14=15,"Full","")) | H14: =IF($E14="","",IF(OR($E14=8,$E14=14,$E14=15,$E14=23,$E15=1,$E16=1),"Fast day","")) | I14: =IFERROR(INDEX(lookup!$E:$E,MATCH($C14,lookup!$D:$D,0)),"") | J14: =IF($I14="","",IF(OR($I14=1,$I14=5,$I14=9),IF($K14="","Long fast month","Long fast month (LEAP)"),"")) | K14: =IFERROR(IF(INDEX(lookup!$G:$G,MATCH($C14,lookup!$D:$D,0))="LEAP","LEAP MONTH - counts as month "&$I14&", flagged for review",""),"")
... A493: =A492+1 | B493: =TEXT(A493,"ddd") | C493: =IFERROR(INDEX(lunar_ref!$B:$B,MATCH($A493,lunar_ref!$A:$A,0)),"") | D493: =IFERROR(INDEX(lunar_ref!$C:$C,MATCH($A493,lunar_ref!$A:$A,0)),"") | E493: =_xlfn.XLOOKUP($D493,lookup!$A:$A,lookup!$B:$B) | F493: =IF($E493=1,"New",IF($E493=15,"Full","")) | H493: =IF($E493="","",IF(OR($E493=8,$E493=14,$E493=15,$E493=23,$E494=1,$E495=1),"Fast day","")) | I493: =IFERROR(INDEX(lookup!$E:$E,MATCH($C493,lookup!$D:$D,0)),"") | J493: =IF($I493="","",IF(OR($I493=1,$I493=5,$I493=9),IF($K493="","Long fast month","Long fast month (LEAP)"),"")) | K493: =IFERROR(IF(INDEX(lookup!$G:$G,MATCH($C493,lookup!$D:$D,0))="LEAP","LEAP MONTH - counts as month "&$I493&", flagged for review",""),"")
A494: =A493+1 | B494: =TEXT(A494,"ddd") | C494: =IFERROR(INDEX(lunar_ref!$B:$B,MATCH($A494,lunar_ref!$A:$A,0)),"") | D494: =IFERROR(INDEX(lunar_ref!$C:$C,MATCH($A494,lunar_ref!$A:$A,0)),"") | E494: =_xlfn.XLOOKUP($D494,lookup!$A:$A,lookup!$B:$B) | F494: =IF($E494=1,"New",IF($E494=15,"Full","")) | H494: =IF($E494="","",IF(OR($E494=8,$E494=14,$E494=15,$E494=23,$E495=1,leap_preview!$E2=1),"Fast day","")) | I494: =IFERROR(INDEX(lookup!$E:$E,MATCH($C494,lookup!$D:$D,0)),"") | J494: =IF($I494="","",IF(OR($I494=1,$I494=5,$I494=9),IF($K494="","Long fast month","Long fast month (LEAP)"),"")) | K494: =IFERROR(IF(INDEX(lookup!$G:$G,MATCH($C494,lookup!$D:$D,0))="LEAP","LEAP MONTH - counts as month "&$I494&", flagged for review",""),"")
A495: =A494+1 | B495: =TEXT(A495,"ddd") | C495: =IFERROR(INDEX(lunar_ref!$B:$B,MATCH($A495,lunar_ref!$A:$A,0)),"") | D495: =IFERROR(INDEX(lunar_ref!$C:$C,MATCH($A495,lunar_ref!$A:$A,0)),"") | E495: =_xlfn.XLOOKUP($D495,lookup!$A:$A,lookup!$B:$B) | F495: =IF($E495=1,"New",IF($E495=15,"Full","")) | H495: =IF($E495="","",IF(OR($E495=8,$E495=14,$E495=15,$E495=23,leap_preview!$E2=1,leap_preview!$E3=1),"Fast day","")) | I495: =IFERROR(INDEX(lookup!$E:$E,MATCH($C495,lookup!$D:$D,0)),"") | J495: =IF($I495="","",IF(OR($I495=1,$I495=5,$I495=9),IF($K495="","Long fast month","Long fast month (LEAP)"),"")) | K495: =IFERROR(IF(INDEX(lookup!$G:$G,MATCH($C495,lookup!$D:$D,0))="LEAP","LEAP MONTH - counts as month "&$I495&", flagged for review",""),"")

Sheet leap_preview
A1: date | B1: weekday | C1: lunar_month | D1: lunar_day | E1: lunar_day_eng | F1: moon_phase | G1: dharma_event | H1: 六齋日 | I1: lunar_month_eng | J1: 三長齋月 | K1: leap_month
A2: =hko_extended!A495+1 | B2: =TEXT(A2,"ddd") | C2: =IFERROR(INDEX(lunar_ref!$B:$B,MATCH($A2,lunar_ref!$A:$A,0)),"") | D2: =IFERROR(INDEX(lunar_ref!$C:$C,MATCH($A2,lunar_ref!$A:$A,0)),"") | E2: =_xlfn.XLOOKUP($D2,lookup!$A:$A,lookup!$B:$B) | F2: =IF($E2=1,"New",IF($E2=15,"Full","")) | H2: =IF($E2="","",IF(OR($E2=8,$E2=14,$E2=15,$E2=23,$E3=1,$E4=1),"Fast day","")) | I2: =IFERROR(INDEX(lookup!$E:$E,MATCH($C2,lookup!$D:$D,0)),"") | J2: =IF($I2="","",IF(OR($I2=1,$I2=5,$I2=9),IF($K2="","Long fast month","Long fast month (LEAP)"),"")) | K2: =IFERROR(IF(INDEX(lookup!$G:$G,MATCH($C2,lookup!$D:$D,0))="LEAP","LEAP MONTH - counts as month "&$I2&", flagged for review",""),"")
A3: =A2+1 | B3: =TEXT(A3,"ddd") | C3: =IFERROR(INDEX(lunar_ref!$B:$B,MATCH($A3,lunar_ref!$A:$A,0)),"") | D3: =IFERROR(INDEX(lunar_ref!$C:$C,MATCH($A3,lunar_ref!$A:$A,0)),"") | E3: =_xlfn.XLOOKUP($D3,lookup!$A:$A,lookup!$B:$B) | F3: =IF($E3=1,"New",IF($E3=15,"Full","")) | H3: =IF($E3="","",IF(OR($E3=8,$E3=14,$E3=15,$E3=23,$E4=1,$E5=1),"Fast day","")) | I3: =IFERROR(INDEX(lookup!$E:$E,MATCH($C3,lookup!$D:$D,0)),"") | J3: =IF($I3="","",IF(OR($I3=1,$I3=5,$I3=9),IF($K3="","Long fast month","Long fast month (LEAP)"),"")) | K3: =IFERROR(IF(INDEX(lookup!$G:$G,MATCH($C3,lookup!$D:$D,0))="LEAP","LEAP MONTH - counts as month "&$I3&", flagged for review",""),"")
A4: =A3+1 | B4: =TEXT(A4,"ddd") | C4: =IFERROR(INDEX(lunar_ref!$B:$B,MATCH($A4,lunar_ref!$A:$A,0)),"") | D4: =IFERROR(INDEX(lunar_ref!$C:$C,MATCH($A4,lunar_ref!$A:$A,0)),"") | E4: =_xlfn.XLOOKUP($D4,lookup!$A:$A,lookup!$B:$B) | F4: =IF($E4=1,"New",IF($E4=15,"Full","")) | H4: =IF($E4="","",IF(OR($E4=8,$E4=14,$E4=15,$E4=23,$E5=1,$E6=1),"Fast day","")) | I4: =IFERROR(INDEX(lookup!$E:$E,MATCH($C4,lookup!$D:$D,0)),"") | J4: =IF($I4="","",IF(OR($I4=1,$I4=5,$I4=9),IF($K4="","Long fast month","Long fast month (LEAP)"),"")) | K4: =IFERROR(IF(INDEX(lookup!$G:$G,MATCH($C4,lookup!$D:$D,0))="LEAP","LEAP MONTH - counts as month "&$I4&", flagged for review",""),"")
A5: =A4+1 | B5: =TEXT(A5,"ddd") | C5: =IFERROR(INDEX(lunar_ref!$B:$B,MATCH($A5,lunar_ref!$A:$A,0)),"") | D5: =IFERROR(INDEX(lunar_ref!$C:$C,MATCH($A5,lunar_ref!$A:$A,0)),"") | E5: =_xlfn.XLOOKUP($D5,lookup!$A:$A,lookup!$B:$B) | F5: =IF($E5=1,"New",IF($E5=15,"Full","")) | H5: =IF($E5="","",IF(OR($E5=8,$E5=14,$E5=15,$E5=23,$E6=1,$E7=1),"Fast day","")) | I5: =IFERROR(INDEX(lookup!$E:$E,MATCH($C5,lookup!$D:$D,0)),"") | J5: =IF($I5="","",IF(OR($I5=1,$I5=5,$I5=9),IF($K5="","Long fast month","Long fast month (LEAP)"),"")) | K5: =IFERROR(IF(INDEX(lookup!$G:$G,MATCH($C5,lookup!$D:$D,0))="LEAP","LEAP MONTH - counts as month "&$I5&", flagged for review",""),"")
A6: =A5+1 | B6: =TEXT(A6,"ddd") | C6: =IFERROR(INDEX(lunar_ref!$B:$B,MATCH($A6,lunar_ref!$A:$A,0)),"") | D6: =IFERROR(INDEX(lunar_ref!$C:$C,MATCH($A6,lunar_ref!$A:$A,0)),"") | E6: =_xlfn.XLOOKUP($D6,lookup!$A:$A,lookup!$B:$B) | F6: =IF($E6=1,"New",IF($E6=15,"Full","")) | H6: =IF($E6="","",IF(OR($E6=8,$E6=14,$E6=15,$E6=23,$E7=1,$E8=1),"Fast day","")) | I6: =IFERROR(INDEX(lookup!$E:$E,MATCH($C6,lookup!$D:$D,0)),"") | J6: =IF($I6="","",IF(OR($I6=1,$I6=5,$I6=9),IF($K6="","Long fast month","Long fast month (LEAP)"),"")) | K6: =IFERROR(IF(INDEX(lookup!$G:$G,MATCH($C6,lookup!$D:$D,0))="LEAP","LEAP MONTH - counts as month "&$I6&", flagged for review",""),"")
A7: =A6+1 | B7: =TEXT(A7,"ddd") | C7: =IFERROR(INDEX(lunar_ref!$B:$B,MATCH($A7,lunar_ref!$A:$A,0)),"") | D7: =IFERROR(INDEX(lunar_ref!$C:$C,MATCH($A7,lunar_ref!$A:$A,0)),"") | E7: =_xlfn.XLOOKUP($D7,lookup!$A:$A,lookup!$B:$B) | F7: =IF($E7=1,"New",IF($E7=15,"Full","")) | H7: =IF($E7="","",IF(OR($E7=8,$E7=14,$E7=15,$E7=23,$E8=1,$E9=1),"Fast day","")) | I7: =IFERROR(INDEX(lookup!$E:$E,MATCH($C7,lookup!$D:$D,0)),"") | J7: =IF($I7="","",IF(OR($I7=1,$I7=5,$I7=9),IF($K7="","Long fast month","Long fast month (LEAP)"),"")) | K7: =IFERROR(IF(INDEX(lookup!$G:$G,MATCH($C7,lookup!$D:$D,0))="LEAP","LEAP MONTH - counts as month "&$I7&", flagged for review",""),"")
A8: =A7+1 | B8: =TEXT(A8,"ddd") | C8: =IFERROR(INDEX(lunar_ref!$B:$B,MATCH($A8,lunar_ref!$A:$A,0)),"") | D8: =IFERROR(INDEX(lunar_ref!$C:$C,MATCH($A8,lunar_ref!$A:$A,0)),"") | E8: =_xlfn.XLOOKUP($D8,lookup!$A:$A,lookup!$B:$B) | F8: =IF($E8=1,"New",IF($E8=15,"Full","")) | H8: =IF($E8="","",IF(OR($E8=8,$E8=14,$E8=15,$E8=23,$E9=1,$E10=1),"Fast day","")) | I8: =IFERROR(INDEX(lookup!$E:$E,MATCH($C8,lookup!$D:$D,0)),"") | J8: =IF($I8="","",IF(OR($I8=1,$I8=5,$I8=9),IF($K8="","Long fast month","Long fast month (LEAP)"),"")) | K8: =IFERROR(IF(INDEX(lookup!$G:$G,MATCH($C8,lookup!$D:$D,0))="LEAP","LEAP MONTH - counts as month "&$I8&", flagged for review",""),"")
A9: =A8+1 | B9: =TEXT(A9,"ddd") | C9: =IFERROR(INDEX(lunar_ref!$B:$B,MATCH($A9,lunar_ref!$A:$A,0)),"") | D9: =IFERROR(INDEX(lunar_ref!$C:$C,MATCH($A9,lunar_ref!$A:$A,0)),"") | E9: =_xlfn.XLOOKUP($D9,lookup!$A:$A,lookup!$B:$B) | F9: =IF($E9=1,"New",IF($E9=15,"Full","")) | H9: =IF($E9="","",IF(OR($E9=8,$E9=14,$E9=15,$E9=23,$E10=1,$E11=1),"Fast day","")) | I9: =IFERROR(INDEX(lookup!$E:$E,MATCH($C9,lookup!$D:$D,0)),"") | J9: =IF($I9="","",IF(OR($I9=1,$I9=5,$I9=9),IF($K9="","Long fast month","Long fast month (LEAP)"),"")) | K9: =IFERROR(IF(INDEX(lookup!$G:$G,MATCH($C9,lookup!$D:$D,0))="LEAP","LEAP MONTH - counts as month "&$I9&", flagged for review",""),"")
A10: =A9+1 | B10: =TEXT(A10,"ddd") | C10: =IFERROR(INDEX(lunar_ref!$B:$B,MATCH($A10,lunar_ref!$A:$A,0)),"") | D10: =IFERROR(INDEX(lunar_ref!$C:$C,MATCH($A10,lunar_ref!$A:$A,0)),"") | E10: =_xlfn.XLOOKUP($D10,lookup!$A:$A,lookup!$B:$B) | F10: =IF($E10=1,"New",IF($E10=15,"Full","")) | H10: =IF($E10="","",IF(OR($E10=8,$E10=14,$E10=15,$E10=23,$E11=1,$E12=1),"Fast day","")) | I10: =IFERROR(INDEX(lookup!$E:$E,MATCH($C10,lookup!$D:$D,0)),"") | J10: =IF($I10="","",IF(OR($I10=1,$I10=5,$I10=9),IF($K10="","Long fast month","Long fast month (LEAP)"),"")) | K10: =IFERROR(IF(INDEX(lookup!$G:$G,MATCH($C10,lookup!$D:$D,0))="LEAP","LEAP MONTH - counts as month "&$I10&", flagged for review",""),"")
A11: =A10+1 | B11: =TEXT(A11,"ddd") | C11: =IFERROR(INDEX(lunar_ref!$B:$B,MATCH($A11,lunar_ref!$A:$A,0)),"") | D11: =IFERROR(INDEX(lunar_ref!$C:$C,MATCH($A11,lunar_ref!$A:$A,0)),"") | E11: =_xlfn.XLOOKUP($D11,lookup!$A:$A,lookup!$B:$B) | F11: =IF($E11=1,"New",IF($E11=15,"Full","")) | H11: =IF($E11="","",IF(OR($E11=8,$E11=14,$E11=15,$E11=23,$E12=1,$E13=1),"Fast day","")) | I11: =IFERROR(INDEX(lookup!$E:$E,MATCH($C11,lookup!$D:$D,0)),"") | J11: =IF($I11="","",IF(OR($I11=1,$I11=5,$I11=9),IF($K11="","Long fast month","Long fast month (LEAP)"),"")) | K11: =IFERROR(IF(INDEX(lookup!$G:$G,MATCH($C11,lookup!$D:$D,0))="LEAP","LEAP MONTH - counts as month "&$I11&", flagged for review",""),"")
A12: =A11+1 | B12: =TEXT(A12,"ddd") | C12: =IFERROR(INDEX(lunar_ref!$B:$B,MATCH($A12,lunar_ref!$A:$A,0)),"") | D12: =IFERROR(INDEX(lunar_ref!$C:$C,MATCH($A12,lunar_ref!$A:$A,0)),"") | E12: =_xlfn.XLOOKUP($D12,lookup!$A:$A,lookup!$B:$B) | F12: =IF($E12=1,"New",IF($E12=15,"Full","")) | H12: =IF($E12="","",IF(OR($E12=8,$E12=14,$E12=15,$E12=23,$E13=1,$E14=1),"Fast day","")) | I12: =IFERROR(INDEX(lookup!$E:$E,MATCH($C12,lookup!$D:$D,0)),"") | J12: =IF($I12="","",IF(OR($I12=1,$I12=5,$I12=9),IF($K12="","Long fast month","Long fast month (LEAP)"),"")) | K12: =IFERROR(IF(INDEX(lookup!$G:$G,MATCH($C12,lookup!$D:$D,0))="LEAP","LEAP MONTH - counts as month "&$I12&", flagged for review",""),"")
A13: =A12+1 | B13: =TEXT(A13,"ddd") | C13: =IFERROR(INDEX(lunar_ref!$B:$B,MATCH($A13,lunar_ref!$A:$A,0)),"") | D13: =IFERROR(INDEX(lunar_ref!$C:$C,MATCH($A13,lunar_ref!$A:$A,0)),"") | E13: =_xlfn.XLOOKUP($D13,lookup!$A:$A,lookup!$B:$B) | F13: =IF($E13=1,"New",IF($E13=15,"Full","")) | H13: =IF($E13="","",IF(OR($E13=8,$E13=14,$E13=15,$E13=23,$E14=1,$E15=1),"Fast day","")) | I13: =IFERROR(INDEX(lookup!$E:$E,MATCH($C13,lookup!$D:$D,0)),"") | J13: =IF($I13="","",IF(OR($I13=1,$I13=5,$I13=9),IF($K13="","Long fast month","Long fast month (LEAP)"),"")) | K13: =IFERROR(IF(INDEX(lookup!$G:$G,MATCH($C13,lookup!$D:$D,0))="LEAP","LEAP MONTH - counts as month "&$I13&", flagged for review",""),"")
A14: =A13+1 | B14: =TEXT(A14,"ddd") | C14: =IFERROR(INDEX(lunar_ref!$B:$B,MATCH($A14,lunar_ref!$A:$A,0)),"") | D14: =IFERROR(INDEX(lunar_ref!$C:$C,MATCH($A14,lunar_ref!$A:$A,0)),"") | E14: =_xlfn.XLOOKUP($D14,lookup!$A:$A,lookup!$B:$B) | F14: =IF($E14=1,"New",IF($E14=15,"Full","")) | H14: =IF($E14="","",IF(OR($E14=8,$E14=14,$E14=15,$E14=23,$E15=1,$E16=1),"Fast day","")) | I14: =IFERROR(INDEX(lookup!$E:$E,MATCH($C14,lookup!$D:$D,0)),"") | J14: =IF($I14="","",IF(OR($I14=1,$I14=5,$I14=9),IF($K14="","Long fast month","Long fast month (LEAP)"),"")) | K14: =IFERROR(IF(INDEX(lookup!$G:$G,MATCH($C14,lookup!$D:$D,0))="LEAP","LEAP MONTH - counts as month "&$I14&", flagged for review",""),"")
... A366: =A365+1 | B366: =TEXT(A366,"ddd") | C366: =IFERROR(INDEX(lunar_ref!$B:$B,MATCH($A366,lunar_ref!$A:$A,0)),"") | D366: =IFERROR(INDEX(lunar_ref!$C:$C,MATCH($A366,lunar_ref!$A:$A,0)),"") | E366: =_xlfn.XLOOKUP($D366,lookup!$A:$A,lookup!$B:$B) | F366: =IF($E366=1,"New",IF($E366=15,"Full","")) | H366: =IF($E366="","",IF(OR($E366=8,$E366=14,$E366=15,$E366=23,$E367=1,$E368=1),"Fast day","")) | I366: =IFERROR(INDEX(lookup!$E:$E,MATCH($C366,lookup!$D:$D,0)),"") | J366: =IF($I366="","",IF(OR($I366=1,$I366=5,$I366=9),IF($K366="","Long fast month","Long fast month (LEAP)"),"")) | K366: =IFERROR(IF(INDEX(lookup!$G:$G,MATCH($C366,lookup!$D:$D,0))="LEAP","LEAP MONTH - counts as month "&$I366&", flagged for review",""),"")

Sheet lookup
A1: lunar_day | B1: eng_day | D1: lunar_month | E1: month_num | F1: gloss | G1: leap?
A2: 三十 | B2: 30 | D2: 正月 | E2: 1 | F2: 1st month (zheng yue, 'principal month') | G2: regular
A3: 初一 | B3: 1 | D3: 一月 | E3: 1 | F3: 1st month (yi yue) - alternate form | G3: regular
A4: 初二 | B4: 2 | D4: 二月 | E4: 2 | F4: 2nd month (er yue) | G4: regular
A5: 初三 | B5: 3 | D5: 三月 | E5: 3 | F5: 3rd month (san yue) | G5: regular
A6: 初四 | B6: 4 | D6: 四月 | E6: 4 | F6: 4th month (si yue) | G6: regular
A7: 初五 | B7: 5 | D7: 五月 | E7: 5 | F7: 5th month (wu yue) | G7: regular
A8: 初六 | B8: 6 | D8: 六月 | E8: 6 | F8: 6th month (liu yue) | G8: regular
A9: 初七 | B9: 7 | D9: 七月 | E9: 7 | F9: 7th month (qi yue) | G9: regular
A10: 初八 | B10: 8 | D10: 八月 | E10: 8 | F10: 8th month (ba yue) | G10: regular
A11: 初九 | B11: 9 | D11: 九月 | E11: 9 | F11: 9th month (jiu yue) | G11: regular
A12: 初十 | B12: 10 | D12: 十月 | E12: 10 | F12: 10th month (shi yue) | G12: regular
A13: 十一 | B13: 11 | D13: 十一月 | E13: 11 | F13: 11th month (shiyi yue) | G13: regular
... A26: 廿四 | B26: 24 | D26: 閏十二月 | E26: 12 | F26: leap 12th month (run shier yue) - counts as month 12 | G26: LEAP
A27: 廿五 | B27: 25
A28: 廿六 | B28: 26
A29: 廿七 | B29: 27
A30: 廿八 | B30: 28
A31: 廿九 | B31: 29
A32: 三 十 | B32: 30

Sheet lunar_ref
A1: date | B1: lunar_month | C1: lunar_day
A2: 46246 | B2: 六月 | C2: 三十
A3: 46247 | B3: 七月 | C3: 初一
A4: 46248 | B4: 七月 | C4: 初二
A5: 46249 | B5: 七月 | C5: 初三
A6: 46250 | B6: 七月 | C6: 初四
A7: 46251 | B7: 七月 | C7: 初五
A8: 46252 | B8: 七月 | C8: 初六
A9: 46253 | B9: 七月 | C9: 初七
A10: 46254 | B10: 七月 | C10: 初八
A11: 46255 | B11: 七月 | C11: 初九
A12: 46256 | B12: 七月 | C12: 初十
A13: 46257 | B13: 七月 | C13: 十一
... A1239: 47483 | B1239: 十一月 | C1239: 廿七

Sheet verification
A1: What is checked, what you decided, and what is still open
A2: CONFIRMED = checked against a source named below. DECIDED = settled by your instruction. CHECK = still open. Nothing in a CHECK row is known to be wrong; it is unverified.
A3: Tabs: drba = from the DRBA printed calendar. hko_extended = built by me from the Hong Kong Observatory tables. lookup and lunar_ref are shared by both.
A5: id | B5: item | C5: status | D5: where it shows up | E5: basis | F5: what would settle it
A6: C1 | B6: Lunar month and day, every row on both data tabs | C6: CONFIRMED | D6: drba!C:D, hko_extended!C:D, lunar_ref | E6: Every row checked against the Hong Kong Observatory Gregorian-Lunar Conversion Tables 2026-2028 (Chinese editions). Zero mismatches. Month boundaries also match the printed DRBA 2026 calendar.
A7: C2 | B7: Seed value in drba!C2 (6th lunar month) | C7: CONFIRMED | D7: drba!C2 | E7: HKO 2026 table: 2026-08-12 is day 30 of the 6th lunar month; the 7th month begins 2026-08-13.
A8: C3 | B8: moon_phase rule: day 1 = New, day 15 = Full | C8: CONFIRMED | D8: drba!F, hko_extended!F | E8: DRBA printed calendars for 2023 and 2026 show a filled circle on the 1st and an open circle on the 15th, leap month included.
A9: C4 | B9: The six fast days are 8, 14, 15, 23, 29, 30 | C9: CONFIRMED | D9: drba!H, hko_extended!H | E9: Fo shuo si tianwang jing (Four Heavenly Kings), Taisho T15n0590: envoys descend on the 8th and 23rd, princes on the 14th and 29th, the kings themselves on the 15th and 30th - two mirrored halves of the month.
A10: C5 | B10: The Brahma Net Sutra does not list which days or months | C10: CONFIRMED | D10: background | E10: Read T24n1484 fascicle 2 in full. 'Six fast days' and 'three long fasting months' appear once, in the 30th light precept, with no day list and no month list.
A11: C6 | B11: Spaced variant of the character for 30 at 2026-11-08 | C11: CONFIRMED | D11: lookup!A32 | E11: Not a data-entry slip. The DRBA 2026 PDF typesets that cell with a space. The lookup table resolves both forms to 30.
A12: D1 | B12: Short months use the last two days, i.e. 28 + 29 | C12: DECIDED | D12: drba!H, hko_extended!H | E12: Your ruling. T15n0590 names the 29th and 30th; a 29-day month has no 30th, so the sheet takes the last two days.
A13: D2 | B13: Long fasting months are the 1st, 5th and 9th | C13: DECIDED | D13: drba!J, hko_extended!J, lookup!D:E | E13: Your ruling. T24n1484 does not name them; the 1st/5th/9th identification is the standard one.
A14: D3 | B14: The six fast days do apply inside a leap month | C14: DECIDED | D14: drba!H, hko_extended!H | E14: Your ruling, and consistent with the DRBA 2023 calendar, which marks the 1st and 15th of the leap 2nd month like any other month. The formula works off the day number, so this already happens.
A15: D4 | B15: The 1st is not a fast day - keep the six-day scheme | C15: DECIDED | D15: drba!H, hko_extended!H | E15: Your ruling. For the record, the 1st is one of the ten fast days listed in the Earth Store Sutra, T13n0412: 1, 8, 14, 15, 18, 23, 24, 28, 29, 30. The sheet does not use that scheme.
A16: D5 | B16: A leap month DOES count as a long fasting month | C16: DECIDED | D16: 三長齋月 and leap_month columns on all three tabs | E16: Your ruling, provisional and deliberately visible: count it, flag it, revisit when it is actually near. A leap 5th month is tagged 'Long fast month (LEAP)', the leap_month column spells it out, and the whole row is banded orange. Note this is the opposite of what the DRBA 2023 calendar suggests, where the leap 2nd month got no repeat of the monthly memorial and no repeat of Guan Yin's birthday - which is why it stays flagged. | F16: First live case is 2028-06-23 to 2028-07-21, visible on the leap_preview tab. If you later decide leap months should not count, change the leap? column in lookup!G15:G26 from LEAP to regular and clear lookup!E15:E26.
A17: K6 | B17: Rows past 2028-12-31 | C17: CHECK | D17: lunar_ref | E17: The reference sheet now runs to 2029-12-31. Drag the date column past that and the lunar columns come up blank. | F17: Extend lunar_ref from the HKO table for the year needed.
A19: Sources read
A20: Fanwang jing (Brahma Net Sutra), T24n1484, fascicle 2, read in full - CBETA text via deerpark.app
A21: Fo shuo si tianwang jing (Four Heavenly Kings), T15n0590, read in full - CBETA text
A22: Dizang pusa benyuan jing (Earth Store Sutra), T13n0412, the ten-fast-day passage - CBETA text
A23: Hong Kong Observatory Gregorian-Lunar Conversion Tables 2026 / 2027 / 2028, Chinese and English editions - hko.gov.hk
A24: DRBA printed calendars 2023, 2024, 2026 (PDF). The March and April 2023 pages were rasterized and read as images, since the leap month question turns on grid position.
A26: NOT read - do not treat as verified
A27: Sanzang fashu fascicle 35 - usually cited as naming the 1st, 5th and 9th months. Seen only quoted.
A28: Da zhidu lun fascicle 13, the six-fast-day passage. Seen only quoted.
A29: Mohe banruo jing fascicle 14, which lists the six days in paired order. Seen only quoted.
A30: Any DRBA or CTTB internal ruling on leap months. None located.
A32: Long fasting month lengths, from the HKO tables
... A38: Notes that used to be cell comments (moved here: comments do not show on mobile and Sheets warns about them)
A39: drba!A1 | B39: Everything on this tab traces to the DRBA printed calendar for 2026: the lunar month, the lunar day, the moon phases and the dharma events. It runs to 2027-01-31, where that calendar stops. Rows after that live on the hko_extended tab, which is sourced from the Hong Kong Observatory instead. The two tabs share the lookup and lunar_ref sheets. The six-fast-day formula on the last two rows looks ahead into hko_extended, since the final days of that lunar month fall there.
A40: drba!H1 | B40: Six fasting days (liu zhai ri): lunar 8, 14, 15, 23 plus the final two days of the lunar month. The last two days are found by lookahead - the lunar day number one or two rows below resets to 1, marking the start of the next lunar month. Handles 29- and 30-day months without hardcoding month lengths. Rule supplied by the user.
A41: drba!I1 | B41: Month name converted to a number against lookup!D:E, mirroring how lunar_day_eng converts the day. Blank if the name is not in that table.
A42: drba!J1 | B42: Three long fasting months (san chang zhai yue): the 1st, 5th and 9th lunar months, tagged on every day of the month. Rule supplied by the user.
A43: drba!C2 | B43: Seed value, hardcoded. 2026-08-12 is day 30 of the 6th lunar month; the 7th month begins 2026-08-13. Source: Hong Kong Observatory, Gregorian-Lunar Calendar Conversion Table of 2026, https://www.hko.gov.hk/en/gts/time/calendar/text/files/T2026e.txt The month it belongs to starts before the sheet does, so it cannot be carried down from a row above.
A44: hko_extended!A1 | B44: Rows past the end of the DRBA 2026 printed calendar. The lunar month and day here do NOT come from a DRBA source: they are looked up from the lunar_ref sheet, which I transcribed from the Hong Kong Observatory Gregorian-Lunar Conversion Tables for 2026-2028. The derived columns (六齋日, lunar_month_eng, 三長齋月) use the same formulas as the drba tab. dharma_event is deliberately empty - DRBA has not published those dates for this range.
A45: leap_preview!A1 | B45: One lunar-ish year, 2028-06-09 to 2029-06-08, built so the leap month can be seen working before it matters. It contains the leap 5th month of 2028 (2028-06-23 to 2028-07-21), the only one in reach of the current reference data. Same sources and same formulas as hko_extended: lunar data from lunar_ref (Hong Kong Observatory), dharma_event empty because DRBA has not published those dates for this range. Leap rows are banded orange.
A46: lookup!D1 | B46: Month names as they appear in the lunar_month column. Rows 15-26 are the leap months, written with a leading run character. They map to the same number as the ordinary month, which is what makes a leap 5th month count as a long fasting month. The leap? column drives the flagging: any row whose month is marked LEAP gets a note in leap_month, a (LEAP) suffix in the long fasting month column, and an orange band across the row. Decision recorded in the verification sheet, item K3.
